Workbook

Sheet GUÍA
A1: CONSOLA DEL REPRESENTANTE ENCARGADO DE CUMPLIMIENTO · Actividades Vulnerables
A2: Herramienta de trabajo diario para quien cumple la LFPIORPI. Actualizada con la Ley (DOF 16-jul-2025), el Reglamento (DOF 27-mar-2026) y las Reglas de Carácter General con el Acuerdo 115/2026 (DOF 7-ago-2026). GMC360 · 360educa.
A4: 1. PRIMERA VEZ (15 minutos)
A5: 1) CONFIG: revisa la tabla de UMA por año y captura el nombre del sujeto obligado, el RFC y el nombre de la persona Representante Encargada de Cumplimiento.
A6: 2) CLIENTES: borra el renglón EJEMPLO-01 y da de alta a tus clientes con sus factores de riesgo, su perfil transaccional y las fechas del expediente.
A7: 3) OPERACIONES: borra el renglón de ejemplo y empieza a registrar operaciones en orden de fecha.
A9: 2. LA RUTINA DEL REC
A10: CADA DÍA
A11: • Registra cada operación en OPERACIONES (fecha, cliente, actividad, monto, efectivo). El motor te dice si identificas, si acumula, si ya hay Aviso y su fecha límite, y si el efectivo está prohibido.
A12: • Lee la columna ALERTAS: exceso de perfil, tercero que paga, cliente de riesgo alto (debida diligencia reforzada), PEP, efectivo prohibido.
A13: • Si algo te huele mal, regístralo en AVISOS_24H en ese momento: el reloj de 24 horas empieza a correr.
A14: • ¿Duda rápida antes de cerrar una venta? Hoja CONSULTA.
... A58: Fuentes: LFPIORPI (DOF 16-jul-2025) · Reglamento (DOF 27-mar-2026) · RCG, Acuerdo 115/2026 (DOF 7-ago-2026) · UMA INEGI (DOF 9-ene-2026). Material de apoyo; no constituye asesoría legal específica.

Sheet TABLERO
A1: TABLERO DEL REPRESENTANTE DE CUMPLIMIENTO
A2: ="Corte: "&DAY(CONFIG!$B$6)&"/"&MONTH(CONFIG!$B$6)&"/"&YEAR(CONFIG!$B$6)&" · "&IF(CONFIG!$B$7="","(captura tus datos en CONFIG)",CONFIG!$B$7&" · REC: "&CONFIG!$B$9) -> Corte: 21/9/2026 · (captura tus datos en CONFIG)
A4: AVISOS Y OPERACIONES | D4: CLIENTES | G4: AVISOS DE 24 HORAS Y RCG
A5: Operaciones del mes en curso | B5: =COUNTIFS(OPERACIONES!$B$6:$B$505,">="&DATE(YEAR(CONFIG!$B$6),MONTH(CONFIG!$B$6),1),OPERACIONES!$B$6:$B$505,"<"&EDATE(DATE(YEAR(CONFIG!$B$6),MONTH(CONFIG!$B$6),1),1)) -> 0 | D5: Clientes registrados | E5: =COUNTA(CLIENTES!$A$6:$A$305) -> 1 | G5: Registros de 24 h pendientes | H5: =COUNTIF(AVISOS_24H!$J$6:$J$105,"Pendiente") -> 0
A6: Monto operado en el mes | B6: =SUMIFS(OPERACIONES!$E$6:$E$505,OPERACIONES!$B$6:$B$505,">="&DATE(YEAR(CONFIG!$B$6),MONTH(CONFIG!$B$6),1),OPERACIONES!$B$6:$B$505,"<"&EDATE(DATE(YEAR(CONFIG!$B$6),MONTH(CONFIG!$B$6),1),1)) -> 0 | D6: Grado ALTO | E6: =COUNTIF(CLIENTES!$Z$6:$Z$305,"Alto") -> 0 | G6: Registros de 24 h VENCIDOS | H6: =COUNTIF(AVISOS_24H!$L$6:$L$105,"VENCIDO") -> 0
A7: Avisos pendientes de presentar | B7: =COUNTIFS(OPERACIONES!$P$6:$P$505,"AVISO*",OPERACIONES!$T$6:$T$505,"<>Presentado") -> 0 | D7: Grado MEDIO | E7: =COUNTIF(CLIENTES!$Z$6:$Z$305,"Medio") -> 1 | G7: Avance obligaciones RCG | H7: =OBLIGACIONES!$B$3 -> 0
A8: Avisos VENCIDOS | B8: =COUNTIF(OPERACIONES!$V$6:$V$505,"VENCIDO") -> 0 | D8: Grado BAJO | E8: =COUNTIF(CLIENTES!$Z$6:$Z$305,"Bajo") -> 0 | G8: Días al 1-mar-2027 (evaluación de riesgo) | H8: =MAX(0,DATE(2027,3,1)-CONFIG!$B$6) -> 161
A9: Próximo vencimiento de Aviso | B9: =IF(MIN(OPERACIONES!$AT$6:$AT$505)=0,"—",MIN(OPERACIONES!$AT$6:$AT$505)) -> — | D9: PEP (nacionales y extranjeras) | E9: =COUNTIF(CLIENTES!$H$6:$H$305,"Nacional")+COUNTIF(CLIENTES!$H$6:$H$305,"Extranjera") -> 0 | G9: Días al 1-jun-2027 (mecanismos automatizados) | H9: =MAX(0,DATE(2027,6,1)-CONFIG!$B$6) -> 253
A10: Operaciones con efectivo prohibido (Art. 32) | B10: =COUNTIF(OPERACIONES!$R$6:$R$505,"PROHIBIDO") -> 0 | D10: Clientes con pendientes | E10: =COUNTIF(CLIENTES!$AE$6:$AE$305,"Revisar") -> 1
A11: Operaciones que exceden el perfil | B11: =SUM(OPERACIONES!$AQ$6:$AQ$505) -> 0 | D11: Evaluaciones de riesgo vencidas | E11: =COUNTIF(CLIENTES!$AB$6:$AB$305,"<"&CONFIG!$B$6) -> 1
A12: Operaciones pagadas por un tercero | B12: =COUNTIF(OPERACIONES!$H$6:$H$505,"Sí") -> 0 | D12: Expedientes incompletos | E12: =COUNTIF(CLIENTES!$P$6:$P$305,"No") -> 0
A13: Meses con Avisos o informe VENCIDO | B13: =COUNTIF(CALENDARIO!$K$6:$K$17,"VENCIDO") -> 8 | D13: Beneficiario Controlador pendiente | E13: =COUNTIF(CLIENTES!$Q$6:$Q$305,"Pendiente") -> 0
A15: Cómo leerlo: todo lo que aparece en rojo es un pendiente. Ve a la hoja indicada y filtra por la columna de semáforo o alertas.
G16: Grado | H16: Clientes
G17: Bajo | H17: =E8 -> 0
G18: Medio | H18: =E7 -> 1
G19: Alto | H19: =E6 -> 0

Sheet OPERACIONES
A1: OPERACIONES — Bitácora y motor de identificación, acumulación y Aviso
A2: Un renglón por operación, de TODOS los clientes, en orden de fecha. El motor acumula por cliente y por actividad (Art. 7 del Reglamento y RCG 19): sólo suma las operaciones que por sí solas alcanzan el umbral de identificación, en periodos de hasta 6 meses desde la primera. Captura lo amarillo; el renglón 6 es un EJEMPLO, bórralo.
A5: Folio | B5: Fecha | C5: ID cliente | D5: Actividad (Fr. - Actividad) | E5: Monto SIN IVA ni accesorios | F5: Pagado en efectivo (CON IVA y accesorios) | G5: Instrumento de pago | H5: ¿Paga un tercero? | I5: Cliente | J5: Grado del cliente | K5: ¿Identificar? | L5: Acumulación | M5: ¿Cuenta para acumular? | N5: Inicio del periodo | O5: Acumulado del periodo | P5: AVISO | Q5: Fecha límite del Aviso | R5: Efectivo (Art. 32) | S5: Alertas | T5: Estatus del Aviso | U5: Fecha en que se presentó | V5: Semáforo del Aviso | W5: Cifra a reportar en el Aviso (total CON IVA) | X5: Observaciones | AA5: aux categoría | AB5: aux id UMA | AC5: aux id $ | AD5: aux aviso UMA | AE5: aux aviso $ | AF5: aux art32 UMA | AG5: aux art32 $ | AH5: aux llave | AI5: aux fila previa | AJ5: aux inicio | AK5: aux acumulado | AL5: aux periodo nuevo | AM5: aux índice cat | AN5: aux periodo abierto | AO5: aux monto mes cliente | AP5: aux perfil | AQ5: aux excede | AR5: aux orden | AS5: aux PEP | AT5: aux vence | AU5: aux Aviso inciso a) | AV5: aux UMA de la fecha | AW5: aux suma 24 h juegos | AX5: aux estatus
A6: =IF(E6="","",ROW()-5) -> 1 | B6: 46086 | C6: EJEMPLO-01 | D6: VI - Piedras y metales preciosos, joyas | E6: 120000 | F6: 0 | G6: Transferencia | H6: No | I6: =IF(C6="","",IFERROR(INDEX(CLIENTES!$B$6:$B$305,MATCH(C6,CLIENTES!$A$6:$A$305,0)),"⚠ ID no registrado")) -> Comercializadora Ejemplo, S.A. de C.V. | J6: =IF(C6="","",IFERROR(INDEX(CLIENTES!$Z$6:$Z$305,MATCH(C6,CLIENTES!$A$6:$A$305,0)),"")) -> Medio | K6: =IF(E6="","",IF(AB6="Siempre","Sí",IF(ISNUMBER(AC6),IF(E6>=AC6,"Sí",IF(AW6>=AC6,"Sí (serie 24 h)","No")),""))) -> Sí | L6: =IF(E6="","",AA6) -> ACUMULA | M6: =IF(E6="","",IF(AA6<>"ACUMULA","No aplica",IF(LEFT(K6,2)="Sí","Sí","No"))) -> Sí | N6: =IF(M6="Sí",AJ6,"") -> 46086 | O6: =IF(M6="Sí",AK6,"") -> 120000 | P6: =IF(AND(LEFT(D6,6)="XIV - ",LEFT(AX6,5)="AVISO"),"Pedimento (R 16): no va al SPPLD",AX6) -> Acumulando | Q6: =IF(LEFT(P6,5)="AVISO",IF(ISNUMBER(B6),DATE(YEAR(B6),MONTH(B6)+1,17),"Falta fecha"),"") | R6: =IF(OR(F6="",F6=0),"",IF(ISNUMBER(AG6),IF(F6>=AG6,"PROHIBIDO","Dentro del límite"),"No aplica")) | S6: =IF(E6="","",MID(IF(AQ6=1," · Excede el perfil declarado","")&IF(H6="Sí"," · Paga un tercero","")&IF(J6="Alto"," · Cliente de riesgo alto: DDR (RCG 23 Ter 3 y 4)","")&IF(AND(AS6<>"",AS6<>"No",AS6<>0)," · PEP","")&IF(R6="PROHIBIDO"," · Efectivo prohibido: no lo recibas (Art. 32)","")&IF(AR6=1," · ⚠ Fecha fuera de orden","")&IF(LEFT(I6,1)="⚠"," · ⚠ Cliente no registrado","")&IF(D6=""," · ⚠ Falta la actividad","")&IF(AND(LEFT(P6,5)="AVISO",W6="")," · Captura la cifra total con IVA para el Aviso","")&IF(AND(ISNUMBER(W6),W6<E6)," · ⚠ La cifra con IVA es menor que el monto sin IVA",""),4,400)) | V6: =IF(LEFT(P6,5)<>"AVISO","",IF(T6="Presentado",IF(AND(ISNUMBER(U6),ISNUMBER(Q6),U6>Q6),"Presentado tarde","Presentado"),IF(NOT(ISNUMBER(Q6)),"Falta fecha",IF(Q6<CONFIG!$B$6,"VENCIDO","Vence en "&(Q6-CONFIG!$B$6)&" días")))) | AA6: =IF(AM6="","",INDEX(CATÁLOGO!$D$5:$D$39,AM6)) -> ACUMULA | AB6: =IF(AM6="","",INDEX(CATÁLOGO!$E$5:$E$39,AM6)) -> 805 | AC6: =IF(AB6="","",IF(ISNUMBER(AB6),AB6*AV6,AB6)) -> 94434.55 | AD6: =IF(AM6="","",INDEX(CATÁLOGO!$F$5:$F$39,AM6)) -> 1605 | AE6: =IF(AD6="","",IF(ISNUMBER(AD6),AD6*AV6,AD6)) -> 188282.55 | AF6: =IF(AM6="","",INDEX(CATÁLOGO!$G$5:$G$39,AM6)) -> 3210 | AG6: =IF(AF6="","",IF(ISNUMBER(AF6),AF6*AV6,AF6)) -> 376565.1 | AH6: =IF(E6="","",C6&"|"&D6) -> EJEMPLO-01|VI - Piedras y metales preciosos, joyas | AI6: =IF(M6<>"Sí",0,SUMPRODUCT(MAX(($AH$5:AH5=AH6)*($M$5:M5="Sí")*ROW($AH$5:AH5)))) -> 0 | AJ6: =IF(M6<>"Sí","",IF(AL6=1,B6,INDEX($AJ:$AJ,AI6))) -> 46086 | AK6: =IF(M6<>"Sí","",IF(AL6=1,E6,INDEX($AK:$AK,AI6)+E6)) -> 120000 | AL6: =IF(M6<>"Sí","",IF(AI6=0,1,IF(INDEX($AN:$AN,AI6)=0,1,IF(B6>=EDATE(INDEX($AJ:$AJ,AI6),6),1,0)))) -> 1 | AM6: =IF(D6="","",IFERROR(MATCH(D6,CATÁLOGO!$C$5:$C$39,0),"")) -> 8 | AN6: =IF(M6<>"Sí","",IF(AND(ISNUMBER(AE6),AK6>=AE6),0,1)) -> 1 | AO6: =IF(OR(E6="",C6="",NOT(ISNUMBER(B6))),"",SUMIFS($E$6:$E$505,$C$6:$C$505,C6,$B$6:$B$505,">="&DATE(YEAR(B6),MONTH(B6),1),$B$6:$B$505,"<"&DATE(YEAR(B6),MONTH(B6)+1,1))) -> 120000 | AP6: =IF(C6="","",IFERROR(INDEX(CLIENTES!$M$6:$M$305,MATCH(C6,CLIENTES!$A$6:$A$305,0)),"")) -> 250000 | AQ6: =IF(AND(ISNUMBER(AO6),ISNUMBER(AP6)),IF(AND(AP6>0,AO6>AP6),1,0),0) -> 0 | AR6: =IF(NOT(ISNUMBER(B6)),0,IF(B6<MAX($B$5:B5),1,0)) -> 0 | AS6: =IF(C6="","",IFERROR(INDEX(CLIENTES!$H$6:$H$305,MATCH(C6,CLIENTES!$A$6:$A$305,0)),"")) -> No | AT6: =IF(AND(LEFT(P6,5)="AVISO",T6<>"Presentado",ISNUMBER(Q6)),Q6,"") | AU6: =IF(AND(D6="XVI - Activos virtuales (PSAV): operación de intercambio/transferencia",M6="Sí",ISNUMBER(AE6)),IF(AK6>=AE6,1,0),0) -> 0 | AV6: =IF(NOT(ISNUMBER(B6)),CONFIG!$B$4,IFERROR(INDEX(CONFIG!$I$5:$I$14,MATCH(IF(MONTH(B6)=1,YEAR(B6)-1,YEAR(B6)),CONFIG!$H$5:$H$14,0)),CONFIG!$B$4)) -> 117.31 | AW6: =IF(AND(LEFT(D6,4)="I - ",ISNUMBER(B6),C6<>""),SUMIFS($E$6:$E$505,$C$6:$C$505,C6,$D$6:$D$505,D6,$B$6:$B$505,">"&(B6-1),$B$6:$B$505,"<="&B6),0) -> 0 | AX6: =IF(E6="","",IF(AD6="Siempre","AVISO (siempre)",IF(AD6="No aplica","Sin Aviso (sólo preparas: Ley 17 XI)",IF(NOT(ISNUMBER(AE6)),"",IF(AA6<>"ACUMULA",IF(E6>=AE6,IF(AND(D6="XVI - Activos virtuales (PSAV): cobro de contraprestación (comisión) por el servicio",COUNTIFS($C$6:$C$505,C6,$B$6:$B$505,">="&INT(B6),$B$6:$B$505,"<"&(INT(B6)+1),$AU$6:$AU$505,1)>0),"En el Aviso del inciso a) (R 31 Bis)","AVISO"),"—"),IF(M6<>"Sí","—",IF(AK6>=AE6,IF(AK6=E6,"AVISO","AVISO (acumulado)"),"Acumulando"))))))) -> Acumulando
A7: =IF(E7="","",ROW()-5) | I7: =IF(C7="","",IFERROR(INDEX(CLIENTES!$B$6:$B$305,MATCH(C7,CLIENTES!$A$6:$A$305,0)),"⚠ ID no registrado")) | J7: =IF(C7="","",IFERROR(INDEX(CLIENTES!$Z$6:$Z$305,MATCH(C7,CLIENTES!$A$6:$A$305,0)),"")) | K7: =IF(E7="","",IF(AB7="Siempre","Sí",IF(ISNUMBER(AC7),IF(E7>=AC7,"Sí",IF(AW7>=AC7,"Sí (serie 24 h)","No")),""))) | L7: =IF(E7="","",AA7) | M7: =IF(E7="","",IF(AA7<>"ACUMULA","No aplica",IF(LEFT(K7,2)="Sí","Sí","No"))) | N7: =IF(M7="Sí",AJ7,"") | O7: =IF(M7="Sí",AK7,"") | P7: =IF(AND(LEFT(D7,6)="XIV - ",LEFT(AX7,5)="AVISO"),"Pedimento (R 16): no va al SPPLD",AX7) | Q7: =IF(LEFT(P7,5)="AVISO",IF(ISNUMBER(B7),DATE(YEAR(B7),MONTH(B7)+1,17),"Falta fecha"),"") | R7: =IF(OR(F7="",F7=0),"",IF(ISNUMBER(AG7),IF(F7>=AG7,"PROHIBIDO","Dentro del límite"),"No aplica")) | S7: =IF(E7="","",MID(IF(AQ7=1," · Excede el perfil declarado","")&IF(H7="Sí"," · Paga un tercero","")&IF(J7="Alto"," · Cliente de riesgo alto: DDR (RCG 23 Ter 3 y 4)","")&IF(AND(AS7<>"",AS7<>"No",AS7<>0)," · PEP","")&IF(R7="PROHIBIDO"," · Efectivo prohibido: no lo recibas (Art. 32)","")&IF(AR7=1," · ⚠ Fecha fuera de orden","")&IF(LEFT(I7,1)="⚠"," · ⚠ Cliente no registrado","")&IF(D7=""," · ⚠ Falta la actividad","")&IF(AND(LEFT(P7,5)="AVISO",W7="")," · Captura la cifra total con IVA para el Aviso","")&IF(AND(ISNUMBER(W7),W7<E7)," · ⚠ La cifra con IVA es menor que el monto sin IVA",""),4,400)) | V7: =IF(LEFT(P7,5)<>"AVISO","",IF(T7="Presentado",IF(AND(ISNUMBER(U7),ISNUMBER(Q7),U7>Q7),"Presentado tarde","Presentado"),IF(NOT(ISNUMBER(Q7)),"Falta fecha",IF(Q7<CONFIG!$B$6,"VENCIDO","Vence en "&(Q7-CONFIG!$B$6)&" días")))) | AA7: =IF(AM7="","",INDEX(CATÁLOGO!$D$5:$D$39,AM7)) | AB7: =IF(AM7="","",INDEX(CATÁLOGO!$E$5:$E$39,AM7)) | AC7: =IF(AB7="","",IF(ISNUMBER(AB7),AB7*AV7,AB7)) | AD7: =IF(AM7="","",INDEX(CATÁLOGO!$F$5:$F$39,AM7)) | AE7: =IF(AD7="","",IF(ISNUMBER(AD7),AD7*AV7,AD7)) | AF7: =IF(AM7="","",INDEX(CATÁLOGO!$G$5:$G$39,AM7)) | AG7: =IF(AF7="","",IF(ISNUMBER(AF7),AF7*AV7,AF7)) | AH7: =IF(E7="","",C7&"|"&D7) | AI7: =IF(M7<>"Sí",0,SUMPRODUCT(MAX(($AH$5:AH6=AH7)*($M$5:M6="Sí")*ROW($AH$5:AH6)))) -> 0 | AJ7: =IF(M7<>"Sí","",IF(AL7=1,B7,INDEX($AJ:$AJ,AI7))) | AK7: =IF(M7<>"Sí","",IF(AL7=1,E7,INDEX($AK:$AK,AI7)+E7)) | AL7: =IF(M7<>"Sí","",IF(AI7=0,1,IF(INDEX($AN:$AN,AI7)=0,1,IF(B7>=EDATE(INDEX($AJ:$AJ,AI7),6),1,0)))) | AM7: =IF(D7="","",IFERROR(MATCH(D7,CATÁLOGO!$C$5:$C$39,0),"")) | AN7: =IF(M7<>"Sí","",IF(AND(ISNUMBER(AE7),AK7>=AE7),0,1)) | AO7: =IF(OR(E7="",C7="",NOT(ISNUMBER(B7))),"",SUMIFS($E$6:$E$505,$C$6:$C$505,C7,$B$6:$B$505,">="&DATE(YEAR(B7),MONTH(B7),1),$B$6:$B$505,"<"&DATE(YEAR(B7),MONTH(B7)+1,1))) | AP7: =IF(C7="","",IFERROR(INDEX(CLIENTES!$M$6:$M$305,MATCH(C7,CLIENTES!$A$6:$A$305,0)),"")) | AQ7: =IF(AND(ISNUMBER(AO7),ISNUMBER(AP7)),IF(AND(AP7>0,AO7>AP7),1,0),0) -> 0 | AR7: =IF(NOT(ISNUMBER(B7)),0,IF(B7<MAX($B$5:B6),1,0)) -> 0 | AS7: =IF(C7="","",IFERROR(INDEX(CLIENTES!$H$6:$H$305,MATCH(C7,CLIENTES!$A$6:$A$305,0)),"")) | AT7: =IF(AND(LEFT(P7,5)="AVISO",T7<>"Presentado",ISNUMBER(Q7)),Q7,"") | AU7: =IF(AND(D7="XVI - Activos virtuales (PSAV): operación de intercambio/transferencia",M7="Sí",ISNUMBER(AE7)),IF(AK7>=AE7,1,0),0) -> 0 | AV7: =IF(NOT(ISNUMBER(B7)),CONFIG!$B$4,IFERROR(INDEX(CONFIG!$I$5:$I$14,MATCH(IF(MONTH(B7)=1,YEAR(B7)-1,YEAR(B7)),CONFIG!$H$5:$H$14,0)),CONFIG!$B$4)) -> 117.31 | AW7: =IF(AND(LEFT(D7,4)="I - ",ISNUMBER(B7),C7<>""),SUMIFS($E$6:$E$505,$C$6:$C$505,C7,$D$6:$D$505,D7,$B$6:$B$505,">"&(B7-1),$B$6:$B$505,"<="&B7),0) -> 0 | AX7: =IF(E7="","",IF(AD7="Siempre","AVISO (siempre)",IF(AD7="No aplica","Sin Aviso (sólo preparas: Ley 17 XI)",IF(NOT(ISNUMBER(AE7)),"",IF(AA7<>"ACUMULA",IF(E7>=AE7,IF(AND(D7="XVI - Activos virtuales (PSAV): cobro de contraprestación (comisión) por el servicio",COUNTIFS($C$6:$C$505,C7,$B$6:$B$505,">="&INT(B7),$B$6:$B$505,"<"&(INT(B7)+1),$AU$6:$AU$505,1)>0),"En el Aviso del inciso a) (R 31 Bis)","AVISO"),"—"),IF(M7<>"Sí","—",IF(AK7>=AE7,IF(AK7=E7,"AVISO","AVISO (acumulado)"),"Acumulando")))))))
A8: =IF(E8="","",ROW()-5) | I8: =IF(C8="","",IFERROR(INDEX(CLIENTES!$B$6:$B$305,MATCH(C8,CLIENTES!$A$6:$A$305,0)),"⚠ ID no registrado")) | J8: =IF(C8="","",IFERROR(INDEX(CLIENTES!$Z$6:$Z$305,MATCH(C8,CLIENTES!$A$6:$A$305,0)),"")) | K8: =IF(E8="","",IF(AB8="Siempre","Sí",IF(ISNUMBER(AC8),IF(E8>=AC8,"Sí",IF(AW8>=AC8,"Sí (serie 24 h)","No")),""))) | L8: =IF(E8="","",AA8) | M8: =IF(E8="","",IF(AA8<>"ACUMULA","No aplica",IF(LEFT(K8,2)="Sí","Sí","No"))) | N8: =IF(M8="Sí",AJ8,"") | O8: =IF(M8="Sí",AK8,"") | P8: =IF(AND(LEFT(D8,6)="XIV - ",LEFT(AX8,5)="AVISO"),"Pedimento (R 16): no va al SPPLD",AX8) | Q8: =IF(LEFT(P8,5)="AVISO",IF(ISNUMBER(B8),DATE(YEAR(B8),MONTH(B8)+1,17),"Falta fecha"),"") | R8: =IF(OR(F8="",F8=0),"",IF(ISNUMBER(AG8),IF(F8>=AG8,"PROHIBIDO","Dentro del límite"),"No aplica")) | S8: =IF(E8="","",MID(IF(AQ8=1," · Excede el perfil declarado","")&IF(H8="Sí"," · Paga un tercero","")&IF(J8="Alto"," · Cliente de riesgo alto: DDR (RCG 23 Ter 3 y 4)","")&IF(AND(AS8<>"",AS8<>"No",AS8<>0)," · PEP","")&IF(R8="PROHIBIDO"," · Efectivo prohibido: no lo recibas (Art. 32)","")&IF(AR8=1," · ⚠ Fecha fuera de orden","")&IF(LEFT(I8,1)="⚠"," · ⚠ Cliente no registrado","")&IF(D8=""," · ⚠ Falta la actividad","")&IF(AND(LEFT(P8,5)="AVISO",W8="")," · Captura la cifra total con IVA para el Aviso","")&IF(AND(ISNUMBER(W8),W8<E8)," · ⚠ La cifra con IVA es menor que el monto sin IVA",""),4,400)) | V8: =IF(LEFT(P8,5)<>"AVISO","",IF(T8="Presentado",IF(AND(ISNUMBER(U8),ISNUMBER(Q8),U8>Q8),"Presentado tarde","Presentado"),IF(NOT(ISNUMBER(Q8)),"Falta fecha",IF(Q8<CONFIG!$B$6,"VENCIDO","Vence en "&(Q8-CONFIG!$B$6)&" días")))) | AA8: =IF(AM8="","",INDEX(CATÁLOGO!$D$5:$D$39,AM8)) | AB8: =IF(AM8="","",INDEX(CATÁLOGO!$E$5:$E$39,AM8)) | AC8: =IF(AB8="","",IF(ISNUMBER(AB8),AB8*AV8,AB8)) | AD8: =IF(AM8="","",INDEX(CATÁLOGO!$F$5:$F$39,AM8)) | AE8: =IF(AD8="","",IF(ISNUMBER(AD8),AD8*AV8,AD8)) | AF8: =IF(AM8="","",INDEX(CATÁLOGO!$G$5:$G$39,AM8)) | AG8: =IF(AF8="","",IF(ISNUMBER(AF8),AF8*AV8,AF8)) | AH8: =IF(E8="","",C8&"|"&D8) | AI8: =IF(M8<>"Sí",0,SUMPRODUCT(MAX(($AH$5:AH7=AH8)*($M$5:M7="Sí")*ROW($AH$5:AH7)))) -> 0 | AJ8: =IF(M8<>"Sí","",IF(AL8=1,B8,INDEX($AJ:$AJ,AI8))) | AK8: =IF(M8<>"Sí","",IF(AL8=1,E8,INDEX($AK:$AK,AI8)+E8)) | AL8: =IF(M8<>"Sí","",IF(AI8=0,1,IF(INDEX($AN:$AN,AI8)=0,1,IF(B8>=EDATE(INDEX($AJ:$AJ,AI8),6),1,0)))) | AM8: =IF(D8="","",IFERROR(MATCH(D8,CATÁLOGO!$C$5:$C$39,0),"")) | AN8: =IF(M8<>"Sí","",IF(AND(ISNUMBER(AE8),AK8>=AE8),0,1)) | AO8: =IF(OR(E8="",C8="",NOT(ISNUMBER(B8))),"",SUMIFS($E$6:$E$505,$C$6:$C$505,C8,$B$6:$B$505,">="&DATE(YEAR(B8),MONTH(B8),1),$B$6:$B$505,"<"&DATE(YEAR(B8),MONTH(B8)+1,1))) | AP8: =IF(C8="","",IFERROR(INDEX(CLIENTES!$M$6:$M$305,MATCH(C8,CLIENTES!$A$6:$A$305,0)),"")) | AQ8: =IF(AND(ISNUMBER(AO8),ISNUMBER(AP8)),IF(AND(AP8>0,AO8>AP8),1,0),0) -> 0 | AR8: =IF(NOT(ISNUMBER(B8)),0,IF(B8<MAX($B$5:B7),1,0)) -> 0 | AS8: =IF(C8="","",IFERROR(INDEX(CLIENTES!$H$6:$H$305,MATCH(C8,CLIENTES!$A$6:$A$305,0)),"")) | AT8: =IF(AND(LEFT(P8,5)="AVISO",T8<>"Presentado",ISNUMBER(Q8)),Q8,"") | AU8: =IF(AND(D8="XVI - Activos virtuales (PSAV): operación de intercambio/transferencia",M8="Sí",ISNUMBER(AE8)),IF(AK8>=AE8,1,0),0) -> 0 | AV8: =IF(NOT(ISNUMBER(B8)),CONFIG!$B$4,IFERROR(INDEX(CONFIG!$I$5:$I$14,MATCH(IF(MONTH(B8)=1,YEAR(B8)-1,YEAR(B8)),CONFIG!$H$5:$H$14,0)),CONFIG!$B$4)) -> 117.31 | AW8: =IF(AND(LEFT(D8,4)="I - ",ISNUMBER(B8),C8<>""),SUMIFS($E$6:$E$505,$C$6:$C$505,C8,$D$6:$D$505,D8,$B$6:$B$505,">"&(B8-1),$B$6:$B$505,"<="&B8),0) -> 0 | AX8: =IF(E8="","",IF(AD8="Siempre","AVISO (siempre)",IF(AD8="No aplica","Sin Aviso (sólo preparas: Ley 17 XI)",IF(NOT(ISNUMBER(AE8)),"",IF(AA8<>"ACUMULA",IF(E8>=AE8,IF(AND(D8="XVI - Activos virtuales (PSAV): cobro de contraprestación (comisión) por el servicio",COUNTIFS($C$6:$C$505,C8,$B$6:$B$505,">="&INT(B8),$B$6:$B$505,"<"&(INT(B8)+1),$AU$6:$AU$505,1)>0),"En el Aviso del inciso a) (R 31 Bis)","AVISO"),"—"),IF(M8<>"Sí","—",IF(AK8>=AE8,IF(AK8=E8,"AVISO","AVISO (acumulado)"),"Acumulando")))))))
A9: =IF(E9="","",ROW()-5) | I9: =IF(C9="","",IFERROR(INDEX(CLIENTES!$B$6:$B$305,MATCH(C9,CLIENTES!$A$6:$A$305,0)),"⚠ ID no registrado")) | J9: =IF(C9="","",IFERROR(INDEX(CLIENTES!$Z$6:$Z$305,MATCH(C9,CLIENTES!$A$6:$A$305,0)),"")) | K9: =IF(E9="","",IF(AB9="Siempre","Sí",IF(ISNUMBER(AC9),IF(E9>=AC9,"Sí",IF(AW9>=AC9,"Sí (serie 24 h)","No")),""))) | L9: =IF(E9="","",AA9) | M9: =IF(E9="","",IF(AA9<>"ACUMULA","No aplica",IF(LEFT(K9,2)="Sí","Sí","No"))) | N9: =IF(M9="Sí",AJ9,"") | O9: =IF(M9="Sí",AK9,"") | P9: =IF(AND(LEFT(D9,6)="XIV - ",LEFT(AX9,5)="AVISO"),"Pedimento (R 16): no va al SPPLD",AX9) | Q9: =IF(LEFT(P9,5)="AVISO",IF(ISNUMBER(B9),DATE(YEAR(B9),MONTH(B9)+1,17),"Falta fecha"),"") | R9: =IF(OR(F9="",F9=0),"",IF(ISNUMBER(AG9),IF(F9>=AG9,"PROHIBIDO","Dentro del límite"),"No aplica")) | S9: =IF(E9="","",MID(IF(AQ9=1," · Excede el perfil declarado","")&IF(H9="Sí"," · Paga un tercero","")&IF(J9="Alto"," · Cliente de riesgo alto: DDR (RCG 23 Ter 3 y 4)","")&IF(AND(AS9<>"",AS9<>"No",AS9<>0)," · PEP","")&IF(R9="PROHIBIDO"," · Efectivo prohibido: no lo recibas (Art. 32)","")&IF(AR9=1," · ⚠ Fecha fuera de orden","")&IF(LEFT(I9,1)="⚠"," · ⚠ Cliente no registrado","")&IF(D9=""," · ⚠ Falta la actividad","")&IF(AND(LEFT(P9,5)="AVISO",W9="")," · Captura la cifra total con IVA para el Aviso","")&IF(AND(ISNUMBER(W9),W9<E9)," · ⚠ La cifra con IVA es menor que el monto sin IVA",""),4,400)) | V9: =IF(LEFT(P9,5)<>"AVISO","",IF(T9="Presentado",IF(AND(ISNUMBER(U9),ISNUMBER(Q9),U9>Q9),"Presentado tarde","Presentado"),IF(NOT(ISNUMBER(Q9)),"Falta fecha",IF(Q9<CONFIG!$B$6,"VENCIDO","Vence en "&(Q9-CONFIG!$B$6)&" días")))) | AA9: =IF(AM9="","",INDEX(CATÁLOGO!$D$5:$D$39,AM9)) | AB9: =IF(AM9="","",INDEX(CATÁLOGO!$E$5:$E$39,AM9)) | AC9: =IF(AB9="","",IF(ISNUMBER(AB9),AB9*AV9,AB9)) | AD9: =IF(AM9="","",INDEX(CATÁLOGO!$F$5:$F$39,AM9)) | AE9: =IF(AD9="","",IF(ISNUMBER(AD9),AD9*AV9,AD9)) | AF9: =IF(AM9="","",INDEX(CATÁLOGO!$G$5:$G$39,AM9)) | AG9: =IF(AF9="","",IF(ISNUMBER(AF9),AF9*AV9,AF9)) | AH9: =IF(E9="","",C9&"|"&D9) | AI9: =IF(M9<>"Sí",0,SUMPRODUCT(MAX(($AH$5:AH8=AH9)*($M$5:M8="Sí")*ROW($AH$5:AH8)))) -> 0 | AJ9: =IF(M9<>"Sí","",IF(AL9=1,B9,INDEX($AJ:$AJ,AI9))) | AK9: =IF(M9<>"Sí","",IF(AL9=1,E9,INDEX($AK:$AK,AI9)+E9)) | AL9: =IF(M9<>"Sí","",IF(AI9=0,1,IF(INDEX($AN:$AN,AI9)=0,1,IF(B9>=EDATE(INDEX($AJ:$AJ,AI9),6),1,0)))) | AM9: =IF(D9="","",IFERROR(MATCH(D9,CATÁLOGO!$C$5:$C$39,0),"")) | AN9: =IF(M9<>"Sí","",IF(AND(ISNUMBER(AE9),AK9>=AE9),0,1)) | AO9: =IF(OR(E9="",C9="",NOT(ISNUMBER(B9))),"",SUMIFS($E$6:$E$505,$C$6:$C$505,C9,$B$6:$B$505,">="&DATE(YEAR(B9),MONTH(B9),1),$B$6:$B$505,"<"&DATE(YEAR(B9),MONTH(B9)+1,1))) | AP9: =IF(C9="","",IFERROR(INDEX(CLIENTES!$M$6:$M$305,MATCH(C9,CLIENTES!$A$6:$A$305,0)),"")) | AQ9: =IF(AND(ISNUMBER(AO9),ISNUMBER(AP9)),IF(AND(AP9>0,AO9>AP9),1,0),0) -> 0 | AR9: =IF(NOT(ISNUMBER(B9)),0,IF(B9<MAX($B$5:B8),1,0)) -> 0 | AS9: =IF(C9="","",IFERROR(INDEX(CLIENTES!$H$6:$H$305,MATCH(C9,CLIENTES!$A$6:$A$305,0)),"")) | AT9: =IF(AND(LEFT(P9,5)="AVISO",T9<>"Presentado",ISNUMBER(Q9)),Q9,"") | AU9: =IF(AND(D9="XVI - Activos virtuales (PSAV): operación de intercambio/transferencia",M9="Sí",ISNUMBER(AE9)),IF(AK9>=AE9,1,0),0) -> 0 | AV9: =IF(NOT(ISNUMBER(B9)),CONFIG!$B$4,IFERROR(INDEX(CONFIG!$I$5:$I$14,MATCH(IF(MONTH(B9)=1,YEAR(B9)-1,YEAR(B9)),CONFIG!$H$5:$H$14,0)),CONFIG!$B$4)) -> 117.31 | AW9: =IF(AND(LEFT(D9,4)="I - ",ISNUMBER(B9),C9<>""),SUMIFS($E$6:$E$505,$C$6:$C$505,C9,$D$6:$D$505,D9,$B$6:$B$505,">"&(B9-1),$B$6:$B$505,"<="&B9),0) -> 0 | AX9: =IF(E9="","",IF(AD9="Siempre","AVISO (siempre)",IF(AD9="No aplica","Sin Aviso (sólo preparas: Ley 17 XI)",IF(NOT(ISNUMBER(AE9)),"",IF(AA9<>"ACUMULA",IF(E9>=AE9,IF(AND(D9="XVI - Activos virtuales (PSAV): cobro de contraprestación (comisión) por el servicio",COUNTIFS($C$6:$C$505,C9,$B$6:$B$505,">="&INT(B9),$B$6:$B$505,"<"&(INT(B9)+1),$AU$6:$AU$505,1)>0),"En el Aviso del inciso a) (R 31 Bis)","AVISO"),"—"),IF(M9<>"Sí","—",IF(AK9>=AE9,IF(AK9=E9,"AVISO","AVISO (acumulado)"),"Acumulando")))))))
A10: =IF(E10="","",ROW()-5) | I10: =IF(C10="","",IFERROR(INDEX(CLIENTES!$B$6:$B$305,MATCH(C10,CLIENTES!$A$6:$A$305,0)),"⚠ ID no registrado")) | J10: =IF(C10="","",IFERROR(INDEX(CLIENTES!$Z$6:$Z$305,MATCH(C10,CLIENTES!$A$6:$A$305,0)),"")) | K10: =IF(E10="","",IF(AB10="Siempre","Sí",IF(ISNUMBER(AC10),IF(E10>=AC10,"Sí",IF(AW10>=AC10,"Sí (serie 24 h)","No")),""))) | L10: =IF(E10="","",AA10) | M10: =IF(E10="","",IF(AA10<>"ACUMULA","No aplica",IF(LEFT(K10,2)="Sí","Sí","No"))) | N10: =IF(M10="Sí",AJ10,"") | O10: =IF(M10="Sí",AK10,"") | P10: =IF(AND(LEFT(D10,6)="XIV - ",LEFT(AX10,5)="AVISO"),"Pedimento (R 16): no va al SPPLD",AX10) | Q10: =IF(LEFT(P10,5)="AVISO",IF(ISNUMBER(B10),DATE(YEAR(B10),MONTH(B10)+1,17),"Falta fecha"),"") | R10: =IF(OR(F10="",F10=0),"",IF(ISNUMBER(AG10),IF(F10>=AG10,"PROHIBIDO","Dentro del límite"),"No aplica")) | S10: =IF(E10="","",MID(IF(AQ10=1," · Excede el perfil declarado","")&IF(H10="Sí"," · Paga un tercero","")&IF(J10="Alto"," · Cliente de riesgo alto: DDR (RCG 23 Ter 3 y 4)","")&IF(AND(AS10<>"",AS10<>"No",AS10<>0)," · PEP","")&IF(R10="PROHIBIDO"," · Efectivo prohibido: no lo recibas (Art. 32)","")&IF(AR10=1," · ⚠ Fecha fuera de orden","")&IF(LEFT(I10,1)="⚠"," · ⚠ Cliente no registrado","")&IF(D10=""," · ⚠ Falta la actividad","")&IF(AND(LEFT(P10,5)="AVISO",W10="")," · Captura la cifra total con IVA para el Aviso","")&IF(AND(ISNUMBER(W10),W10<E10)," · ⚠ La cifra con IVA es menor que el monto sin IVA",""),4,400)) | V10: =IF(LEFT(P10,5)<>"AVISO","",IF(T10="Presentado",IF(AND(ISNUMBER(U10),ISNUMBER(Q10),U10>Q10),"Presentado tarde","Presentado"),IF(NOT(ISNUMBER(Q10)),"Falta fecha",IF(Q10<CONFIG!$B$6,"VENCIDO","Vence en "&(Q10-CONFIG!$B$6)&" días")))) | AA10: =IF(AM10="","",INDEX(CATÁLOGO!$D$5:$D$39,AM10)) | AB10: =IF(AM10="","",INDEX(CATÁLOGO!$E$5:$E$39,AM10)) | AC10: =IF(AB10="","",IF(ISNUMBER(AB10),AB10*AV10,AB10)) | AD10: =IF(AM10="","",INDEX(CATÁLOGO!$F$5:$F$39,AM10)) | AE10: =IF(AD10="","",IF(ISNUMBER(AD10),AD10*AV10,AD10)) | AF10: =IF(AM10="","",INDEX(CATÁLOGO!$G$5:$G$39,AM10)) | AG10: =IF(AF10="","",IF(ISNUMBER(AF10),AF10*AV10,AF10)) | AH10: =IF(E10="","",C10&"|"&D10) | AI10: =IF(M10<>"Sí",0,SUMPRODUCT(MAX(($AH$5:AH9=AH10)*($M$5:M9="Sí")*ROW($AH$5:AH9)))) -> 0 | AJ10: =IF(M10<>"Sí","",IF(AL10=1,B10,INDEX($AJ:$AJ,AI10))) | AK10: =IF(M10<>"Sí","",IF(AL10=1,E10,INDEX($AK:$AK,AI10)+E10)) | AL10: =IF(M10<>"Sí","",IF(AI10=0,1,IF(INDEX($AN:$AN,AI10)=0,1,IF(B10>=EDATE(INDEX($AJ:$AJ,AI10),6),1,0)))) | AM10: =IF(D10="","",IFERROR(MATCH(D10,CATÁLOGO!$C$5:$C$39,0),"")) | AN10: =IF(M10<>"Sí","",IF(AND(ISNUMBER(AE10),AK10>=AE10),0,1)) | AO10: =IF(OR(E10="",C10="",NOT(ISNUMBER(B10))),"",SUMIFS($E$6:$E$505,$C$6:$C$505,C10,$B$6:$B$505,">="&DATE(YEAR(B10),MONTH(B10),1),$B$6:$B$505,"<"&DATE(YEAR(B10),MONTH(B10)+1,1))) | AP10: =IF(C10="","",IFERROR(INDEX(CLIENTES!$M$6:$M$305,MATCH(C10,CLIENTES!$A$6:$A$305,0)),"")) | AQ10: =IF(AND(ISNUMBER(AO10),ISNUMBER(AP10)),IF(AND(AP10>0,AO10>AP10),1,0),0) -> 0 | AR10: =IF(NOT(ISNUMBER(B10)),0,IF(B10<MAX($B$5:B9),1,0)) -> 0 | AS10: =IF(C10="","",IFERROR(INDEX(CLIENTES!$H$6:$H$305,MATCH(C10,CLIENTES!$A$6:$A$305,0)),"")) | AT10: =IF(AND(LEFT(P10,5)="AVISO",T10<>"Presentado",ISNUMBER(Q10)),Q10,"") | AU10: =IF(AND(D10="XVI - Activos virtuales (PSAV): operación de intercambio/transferencia",M10="Sí",ISNUMBER(AE10)),IF(AK10>=AE10,1,0),0) -> 0 | AV10: =IF(NOT(ISNUMBER(B10)),CONFIG!$B$4,IFERROR(INDEX(CONFIG!$I$5:$I$14,MATCH(IF(MONTH(B10)=1,YEAR(B10)-1,YEAR(B10)),CONFIG!$H$5:$H$14,0)),CONFIG!$B$4)) -> 117.31 | AW10: =IF(AND(LEFT(D10,4)="I - ",ISNUMBER(B10),C10<>""),SUMIFS($E$6:$E$505,$C$6:$C$505,C10,$D$6:$D$505,D10,$B$6:$B$505,">"&(B10-1),$B$6:$B$505,"<="&B10),0) -> 0 | AX10: =IF(E10="","",IF(AD10="Siempre","AVISO (siempre)",IF(AD10="No aplica","Sin Aviso (sólo preparas: Ley 17 XI)",IF(NOT(ISNUMBER(AE10)),"",IF(AA10<>"ACUMULA",IF(E10>=AE10,IF(AND(D10="XVI - Activos virtuales (PSAV): cobro de contraprestación (comisión) por el servicio",COUNTIFS($C$6:$C$505,C10,$B$6:$B$505,">="&INT(B10),$B$6:$B$505,"<"&(INT(B10)+1),$AU$6:$AU$505,1)>0),"En el Aviso del inciso a) (R 31 Bis)","AVISO"),"—"),IF(M10<>"Sí","—",IF(AK10>=AE10,IF(AK10=E10,"AVISO","AVISO (acumulado)"),"Acumulando")))))))
A11: =IF(E11="","",ROW()-5) | I11: =IF(C11="","",IFERROR(INDEX(CLIENTES!$B$6:$B$305,MATCH(C11,CLIENTES!$A$6:$A$305,0)),"⚠ ID no registrado")) | J11: =IF(C11="","",IFERROR(INDEX(CLIENTES!$Z$6:$Z$305,MATCH(C11,CLIENTES!$A$6:$A$305,0)),"")) | K11: =IF(E11="","",IF(AB11="Siempre","Sí",IF(ISNUMBER(AC11),IF(E11>=AC11,"Sí",IF(AW11>=AC11,"Sí (serie 24 h)","No")),""))) | L11: =IF(E11="","",AA11) | M11: =IF(E11="","",IF(AA11<>"ACUMULA","No aplica",IF(LEFT(K11,2)="Sí","Sí","No"))) | N11: =IF(M11="Sí",AJ11,"") | O11: =IF(M11="Sí",AK11,"") | P11: =IF(AND(LEFT(D11,6)="XIV - ",LEFT(AX11,5)="AVISO"),"Pedimento (R 16): no va al SPPLD",AX11) | Q11: =IF(LEFT(P11,5)="AVISO",IF(ISNUMBER(B11),DATE(YEAR(B11),MONTH(B11)+1,17),"Falta fecha"),"") | R11: =IF(OR(F11="",F11=0),"",IF(ISNUMBER(AG11),IF(F11>=AG11,"PROHIBIDO","Dentro del límite"),"No aplica")) | S11: =IF(E11="","",MID(IF(AQ11=1," · Excede el perfil declarado","")&IF(H11="Sí"," · Paga un tercero","")&IF(J11="Alto"," · Cliente de riesgo alto: DDR (RCG 23 Ter 3 y 4)","")&IF(AND(AS11<>"",AS11<>"No",AS11<>0)," · PEP","")&IF(R11="PROHIBIDO"," · Efectivo prohibido: no lo recibas (Art. 32)","")&IF(AR11=1," · ⚠ Fecha fuera de orden","")&IF(LEFT(I11,1)="⚠"," · ⚠ Cliente no registrado","")&IF(D11=""," · ⚠ Falta la actividad","")&IF(AND(LEFT(P11,5)="AVISO",W11="")," · Captura la cifra total con IVA para el Aviso","")&IF(AND(ISNUMBER(W11),W11<E11)," · ⚠ La cifra con IVA es menor que el monto sin IVA",""),4,400)) | V11: =IF(LEFT(P11,5)<>"AVISO","",IF(T11="Presentado",IF(AND(ISNUMBER(U11),ISNUMBER(Q11),U11>Q11),"Presentado tarde","Presentado"),IF(NOT(ISNUMBER(Q11)),"Falta fecha",IF(Q11<CONFIG!$B$6,"VENCIDO","Vence en "&(Q11-CONFIG!$B$6)&" días")))) | AA11: =IF(AM11="","",INDEX(CATÁLOGO!$D$5:$D$39,AM11)) | AB11: =IF(AM11="","",INDEX(CATÁLOGO!$E$5:$E$39,AM11)) | AC11: =IF(AB11="","",IF(ISNUMBER(AB11),AB11*AV11,AB11)) | AD11: =IF(AM11="","",INDEX(CATÁLOGO!$F$5:$F$39,AM11)) | AE11: =IF(AD11="","",IF(ISNUMBER(AD11),AD11*AV11,AD11)) | AF11: =IF(AM11="","",INDEX(CATÁLOGO!$G$5:$G$39,AM11)) | AG11: =IF(AF11="","",IF(ISNUMBER(AF11),AF11*AV11,AF11)) | AH11: =IF(E11="","",C11&"|"&D11) | AI11: =IF(M11<>"Sí",0,SUMPRODUCT(MAX(($AH$5:AH10=AH11)*($M$5:M10="Sí")*ROW($AH$5:AH10)))) -> 0 | AJ11: =IF(M11<>"Sí","",IF(AL11=1,B11,INDEX($AJ:$AJ,AI11))) | AK11: =IF(M11<>"Sí","",IF(AL11=1,E11,INDEX($AK:$AK,AI11)+E11)) | AL11: =IF(M11<>"Sí","",IF(AI11=0,1,IF(INDEX($AN:$AN,AI11)=0,1,IF(B11>=EDATE(INDEX($AJ:$AJ,AI11),6),1,0)))) | AM11: =IF(D11="","",IFERROR(MATCH(D11,CATÁLOGO!$C$5:$C$39,0),"")) | AN11: =IF(M11<>"Sí","",IF(AND(ISNUMBER(AE11),AK11>=AE11),0,1)) | AO11: =IF(OR(E11="",C11="",NOT(ISNUMBER(B11))),"",SUMIFS($E$6:$E$505,$C$6:$C$505,C11,$B$6:$B$505,">="&DATE(YEAR(B11),MONTH(B11),1),$B$6:$B$505,"<"&DATE(YEAR(B11),MONTH(B11)+1,1))) | AP11: =IF(C11="","",IFERROR(INDEX(CLIENTES!$M$6:$M$305,MATCH(C11,CLIENTES!$A$6:$A$305,0)),"")) | AQ11: =IF(AND(ISNUMBER(AO11),ISNUMBER(AP11)),IF(AND(AP11>0,AO11>AP11),1,0),0) -> 0 | AR11: =IF(NOT(ISNUMBER(B11)),0,IF(B11<MAX($B$5:B10),1,0)) -> 0 | AS11: =IF(C11="","",IFERROR(INDEX(CLIENTES!$H$6:$H$305,MATCH(C11,CLIENTES!$A$6:$A$305,0)),"")) | AT11: =IF(AND(LEFT(P11,5)="AVISO",T11<>"Presentado",ISNUMBER(Q11)),Q11,"") | AU11: =IF(AND(D11="XVI - Activos virtuales (PSAV): operación de intercambio/transferencia",M11="Sí",ISNUMBER(AE11)),IF(AK11>=AE11,1,0),0) -> 0 | AV11: =IF(NOT(ISNUMBER(B11)),CONFIG!$B$4,IFERROR(INDEX(CONFIG!$I$5:$I$14,MATCH(IF(MONTH(B11)=1,YEAR(B11)-1,YEAR(B11)),CONFIG!$H$5:$H$14,0)),CONFIG!$B$4)) -> 117.31 | AW11: =IF(AND(LEFT(D11,4)="I - ",ISNUMBER(B11),C11<>""),SUMIFS($E$6:$E$505,$C$6:$C$505,C11,$D$6:$D$505,D11,$B$6:$B$505,">"&(B11-1),$B$6:$B$505,"<="&B11),0) -> 0 | AX11: =IF(E11="","",IF(AD11="Siempre","AVISO (siempre)",IF(AD11="No aplica","Sin Aviso (sólo preparas: Ley 17 XI)",IF(NOT(ISNUMBER(AE11)),"",IF(AA11<>"ACUMULA",IF(E11>=AE11,IF(AND(D11="XVI - Activos virtuales (PSAV): cobro de contraprestación (comisión) por el servicio",COUNTIFS($C$6:$C$505,C11,$B$6:$B$505,">="&INT(B11),$B$6:$B$505,"<"&(INT(B11)+1),$AU$6:$AU$505,1)>0),"En el Aviso del inciso a) (R 31 Bis)","AVISO"),"—"),IF(M11<>"Sí","—",IF(AK11>=AE11,IF(AK11=E11,"AVISO","AVISO (acumulado)"),"Acumulando")))))))
A12: =IF(E12="","",ROW()-5) | I12: =IF(C12="","",IFERROR(INDEX(CLIENTES!$B$6:$B$305,MATCH(C12,CLIENTES!$A$6:$A$305,0)),"⚠ ID no registrado")) | J12: =IF(C12="","",IFERROR(INDEX(CLIENTES!$Z$6:$Z$305,MATCH(C12,CLIENTES!$A$6:$A$305,0)),"")) | K12: =IF(E12="","",IF(AB12="Siempre","Sí",IF(ISNUMBER(AC12),IF(E12>=AC12,"Sí",IF(AW12>=AC12,"Sí (serie 24 h)","No")),""))) | L12: =IF(E12="","",AA12) | M12: =IF(E12="","",IF(AA12<>"ACUMULA","No aplica",IF(LEFT(K12,2)="Sí","Sí","No"))) | N12: =IF(M12="Sí",AJ12,"") | O12: =IF(M12="Sí",AK12,"") | P12: =IF(AND(LEFT(D12,6)="XIV - ",LEFT(AX12,5)="AVISO"),"Pedimento (R 16): no va al SPPLD",AX12) | Q12: =IF(LEFT(P12,5)="AVISO",IF(ISNUMBER(B12),DATE(YEAR(B12),MONTH(B12)+1,17),"Falta fecha"),"") | R12: =IF(OR(F12="",F12=0),"",IF(ISNUMBER(AG12),IF(F12>=AG12,"PROHIBIDO","Dentro del límite"),"No aplica")) | S12: =IF(E12="","",MID(IF(AQ12=1," · Excede el perfil declarado","")&IF(H12="Sí"," · Paga un tercero","")&IF(J12="Alto"," · Cliente de riesgo alto: DDR (RCG 23 Ter 3 y 4)","")&IF(AND(AS12<>"",AS12<>"No",AS12<>0)," · PEP","")&IF(R12="PROHIBIDO"," · Efectivo prohibido: no lo recibas (Art. 32)","")&IF(AR12=1," · ⚠ Fecha fuera de orden","")&IF(LEFT(I12,1)="⚠"," · ⚠ Cliente no registrado","")&IF(D12=""," · ⚠ Falta la actividad","")&IF(AND(LEFT(P12,5)="AVISO",W12="")," · Captura la cifra total con IVA para el Aviso","")&IF(AND(ISNUMBER(W12),W12<E12)," · ⚠ La cifra con IVA es menor que el monto sin IVA",""),4,400)) | V12: =IF(LEFT(P12,5)<>"AVISO","",IF(T12="Presentado",IF(AND(ISNUMBER(U12),ISNUMBER(Q12),U12>Q12),"Presentado tarde","Presentado"),IF(NOT(ISNUMBER(Q12)),"Falta fecha",IF(Q12<CONFIG!$B$6,"VENCIDO","Vence en "&(Q12-CONFIG!$B$6)&" días")))) | AA12: =IF(AM12="","",INDEX(CATÁLOGO!$D$5:$D$39,AM12)) | AB12: =IF(AM12="","",INDEX(CATÁLOGO!$E$5:$E$39,AM12)) | AC12: =IF(AB12="","",IF(ISNUMBER(AB12),AB12*AV12,AB12)) | AD12: =IF(AM12="","",INDEX(CATÁLOGO!$F$5:$F$39,AM12)) | AE12: =IF(AD12="","",IF(ISNUMBER(AD12),AD12*AV12,AD12)) | AF12: =IF(AM12="","",INDEX(CATÁLOGO!$G$5:$G$39,AM12)) | AG12: =IF(AF12="","",IF(ISNUMBER(AF12),AF12*AV12,AF12)) | AH12: =IF(E12="","",C12&"|"&D12) | AI12: =IF(M12<>"Sí",0,SUMPRODUCT(MAX(($AH$5:AH11=AH12)*($M$5:M11="Sí")*ROW($AH$5:AH11)))) -> 0 | AJ12: =IF(M12<>"Sí","",IF(AL12=1,B12,INDEX($AJ:$AJ,AI12))) | AK12: =IF(M12<>"Sí","",IF(AL12=1,E12,INDEX($AK:$AK,AI12)+E12)) | AL12: =IF(M12<>"Sí","",IF(AI12=0,1,IF(INDEX($AN:$AN,AI12)=0,1,IF(B12>=EDATE(INDEX($AJ:$AJ,AI12),6),1,0)))) | AM12: =IF(D12="","",IFERROR(MATCH(D12,CATÁLOGO!$C$5:$C$39,0),"")) | AN12: =IF(M12<>"Sí","",IF(AND(ISNUMBER(AE12),AK12>=AE12),0,1)) | AO12: =IF(OR(E12="",C12="",NOT(ISNUMBER(B12))),"",SUMIFS($E$6:$E$505,$C$6:$C$505,C12,$B$6:$B$505,">="&DATE(YEAR(B12),MONTH(B12),1),$B$6:$B$505,"<"&DATE(YEAR(B12),MONTH(B12)+1,1))) | AP12: =IF(C12="","",IFERROR(INDEX(CLIENTES!$M$6:$M$305,MATCH(C12,CLIENTES!$A$6:$A$305,0)),"")) | AQ12: =IF(AND(ISNUMBER(AO12),ISNUMBER(AP12)),IF(AND(AP12>0,AO12>AP12),1,0),0) -> 0 | AR12: =IF(NOT(ISNUMBER(B12)),0,IF(B12<MAX($B$5:B11),1,0)) -> 0 | AS12: =IF(C12="","",IFERROR(INDEX(CLIENTES!$H$6:$H$305,MATCH(C12,CLIENTES!$A$6:$A$305,0)),"")) | AT12: =IF(AND(LEFT(P12,5)="AVISO",T12<>"Presentado",ISNUMBER(Q12)),Q12,"") | AU12: =IF(AND(D12="XVI - Activos virtuales (PSAV): operación de intercambio/transferencia",M12="Sí",ISNUMBER(AE12)),IF(AK12>=AE12,1,0),0) -> 0 | AV12: =IF(NOT(ISNUMBER(B12)),CONFIG!$B$4,IFERROR(INDEX(CONFIG!$I$5:$I$14,MATCH(IF(MONTH(B12)=1,YEAR(B12)-1,YEAR(B12)),CONFIG!$H$5:$H$14,0)),CONFIG!$B$4)) -> 117.31 | AW12: =IF(AND(LEFT(D12,4)="I - ",ISNUMBER(B12),C12<>""),SUMIFS($E$6:$E$505,$C$6:$C$505,C12,$D$6:$D$505,D12,$B$6:$B$505,">"&(B12-1),$B$6:$B$505,"<="&B12),0) -> 0 | AX12: =IF(E12="","",IF(AD12="Siempre","AVISO (siempre)",IF(AD12="No aplica","Sin Aviso (sólo preparas: Ley 17 XI)",IF(NOT(ISNUMBER(AE12)),"",IF(AA12<>"ACUMULA",IF(E12>=AE12,IF(AND(D12="XVI - Activos virtuales (PSAV): cobro de contraprestación (comisión) por el servicio",COUNTIFS($C$6:$C$505,C12,$B$6:$B$505,">="&INT(B12),$B$6:$B$505,"<"&(INT(B12)+1),$AU$6:$AU$505,1)>0),"En el Aviso del inciso a) (R 31 Bis)","AVISO"),"—"),IF(M12<>"Sí","—",IF(AK12>=AE12,IF(AK12=E12,"AVISO","AVISO (acumulado)"),"Acumulando")))))))
A13: =IF(E13="","",ROW()-5) | I13: =IF(C13="","",IFERROR(INDEX(CLIENTES!$B$6:$B$305,MATCH(C13,CLIENTES!$A$6:$A$305,0)),"⚠ ID no registrado")) | J13: =IF(C13="","",IFERROR(INDEX(CLIENTES!$Z$6:$Z$305,MATCH(C13,CLIENTES!$A$6:$A$305,0)),"")) | K13: =IF(E13="","",IF(AB13="Siempre","Sí",IF(ISNUMBER(AC13),IF(E13>=AC13,"Sí",IF(AW13>=AC13,"Sí (serie 24 h)","No")),""))) | L13: =IF(E13="","",AA13) | M13: =IF(E13="","",IF(AA13<>"ACUMULA","No aplica",IF(LEFT(K13,2)="Sí","Sí","No"))) | N13: =IF(M13="Sí",AJ13,"") | O13: =IF(M13="Sí",AK13,"") | P13: =IF(AND(LEFT(D13,6)="XIV - ",LEFT(AX13,5)="AVISO"),"Pedimento (R 16): no va al SPPLD",AX13) | Q13: =IF(LEFT(P13,5)="AVISO",IF(ISNUMBER(B13),DATE(YEAR(B13),MONTH(B13)+1,17),"Falta fecha"),"") | R13: =IF(OR(F13="",F13=0),"",IF(ISNUMBER(AG13),IF(F13>=AG13,"PROHIBIDO","Dentro del límite"),"No aplica")) | S13: =IF(E13="","",MID(IF(AQ13=1," · Excede el perfil declarado","")&IF(H13="Sí"," · Paga un tercero","")&IF(J13="Alto"," · Cliente de riesgo alto: DDR (RCG 23 Ter 3 y 4)","")&IF(AND(AS13<>"",AS13<>"No",AS13<>0)," · PEP","")&IF(R13="PROHIBIDO"," · Efectivo prohibido: no lo recibas (Art. 32)","")&IF(AR13=1," · ⚠ Fecha fuera de orden","")&IF(LEFT(I13,1)="⚠"," · ⚠ Cliente no registrado","")&IF(D13=""," · ⚠ Falta la actividad","")&IF(AND(LEFT(P13,5)="AVISO",W13="")," · Captura la cifra total con IVA para el Aviso","")&IF(AND(ISNUMBER(W13),W13<E13)," · ⚠ La cifra con IVA es menor que el monto sin IVA",""),4,400)) | V13: =IF(LEFT(P13,5)<>"AVISO","",IF(T13="Presentado",IF(AND(ISNUMBER(U13),ISNUMBER(Q13),U13>Q13),"Presentado tarde","Presentado"),IF(NOT(ISNUMBER(Q13)),"Falta fecha",IF(Q13<CONFIG!$B$6,"VENCIDO","Vence en "&(Q13-CONFIG!$B$6)&" días")))) | AA13: =IF(AM13="","",INDEX(CATÁLOGO!$D$5:$D$39,AM13)) | AB13: =IF(AM13="","",INDEX(CATÁLOGO!$E$5:$E$39,AM13)) | AC13: =IF(AB13="","",IF(ISNUMBER(AB13),AB13*AV13,AB13)) | AD13: =IF(AM13="","",INDEX(CATÁLOGO!$F$5:$F$39,AM13)) | AE13: =IF(AD13="","",IF(ISNUMBER(AD13),AD13*AV13,AD13)) | AF13: =IF(AM13="","",INDEX(CATÁLOGO!$G$5:$G$39,AM13)) | AG13: =IF(AF13="","",IF(ISNUMBER(AF13),AF13*AV13,AF13)) | AH13: =IF(E13="","",C13&"|"&D13) | AI13: =IF(M13<>"Sí",0,SUMPRODUCT(MAX(($AH$5:AH12=AH13)*($M$5:M12="Sí")*ROW($AH$5:AH12)))) -> 0 | AJ13: =IF(M13<>"Sí","",IF(AL13=1,B13,INDEX($AJ:$AJ,AI13))) | AK13: =IF(M13<>"Sí","",IF(AL13=1,E13,INDEX($AK:$AK,AI13)+E13)) | AL13: =IF(M13<>"Sí","",IF(AI13=0,1,IF(INDEX($AN:$AN,AI13)=0,1,IF(B13>=EDATE(INDEX($AJ:$AJ,AI13),6),1,0)))) | AM13: =IF(D13="","",IFERROR(MATCH(D13,CATÁLOGO!$C$5:$C$39,0),"")) | AN13: =IF(M13<>"Sí","",IF(AND(ISNUMBER(AE13),AK13>=AE13),0,1)) | AO13: =IF(OR(E13="",C13="",NOT(ISNUMBER(B13))),"",SUMIFS($E$6:$E$505,$C$6:$C$505,C13,$B$6:$B$505,">="&DATE(YEAR(B13),MONTH(B13),1),$B$6:$B$505,"<"&DATE(YEAR(B13),MONTH(B13)+1,1))) | AP13: =IF(C13="","",IFERROR(INDEX(CLIENTES!$M$6:$M$305,MATCH(C13,CLIENTES!$A$6:$A$305,0)),"")) | AQ13: =IF(AND(ISNUMBER(AO13),ISNUMBER(AP13)),IF(AND(AP13>0,AO13>AP13),1,0),0) -> 0 | AR13: =IF(NOT(ISNUMBER(B13)),0,IF(B13<MAX($B$5:B12),1,0)) -> 0 | AS13: =IF(C13="","",IFERROR(INDEX(CLIENTES!$H$6:$H$305,MATCH(C13,CLIENTES!$A$6:$A$305,0)),"")) | AT13: =IF(AND(LEFT(P13,5)="AVISO",T13<>"Presentado",ISNUMBER(Q13)),Q13,"") | AU13: =IF(AND(D13="XVI - Activos virtuales (PSAV): operación de intercambio/transferencia",M13="Sí",ISNUMBER(AE13)),IF(AK13>=AE13,1,0),0) -> 0 | AV13: =IF(NOT(ISNUMBER(B13)),CONFIG!$B$4,IFERROR(INDEX(CONFIG!$I$5:$I$14,MATCH(IF(MONTH(B13)=1,YEAR(B13)-1,YEAR(B13)),CONFIG!$H$5:$H$14,0)),CONFIG!$B$4)) -> 117.31 | AW13: =IF(AND(LEFT(D13,4)="I - ",ISNUMBER(B13),C13<>""),SUMIFS($E$6:$E$505,$C$6:$C$505,C13,$D$6:$D$505,D13,$B$6:$B$505,">"&(B13-1),$B$6:$B$505,"<="&B13),0) -> 0 | AX13: =IF(E13="","",IF(AD13="Siempre","AVISO (siempre)",IF(AD13="No aplica","Sin Aviso (sólo preparas: Ley 17 XI)",IF(NOT(ISNUMBER(AE13)),"",IF(AA13<>"ACUMULA",IF(E13>=AE13,IF(AND(D13="XVI - Activos virtuales (PSAV): cobro de contraprestación (comisión) por el servicio",COUNTIFS($C$6:$C$505,C13,$B$6:$B$505,">="&INT(B13),$B$6:$B$505,"<"&(INT(B13)+1),$AU$6:$AU$505,1)>0),"En el Aviso del inciso a) (R 31 Bis)","AVISO"),"—"),IF(M13<>"Sí","—",IF(AK13>=AE13,IF(AK13=E13,"AVISO","AVISO (acumulado)"),"Acumulando")))))))
A14: =IF(E14="","",ROW()-5) | I14: =IF(C14="","",IFERROR(INDEX(CLIENTES!$B$6:$B$305,MATCH(C14,CLIENTES!$A$6:$A$305,0)),"⚠ ID no registrado")) | J14: =IF(C14="","",IFERROR(INDEX(CLIENTES!$Z$6:$Z$305,MATCH(C14,CLIENTES!$A$6:$A$305,0)),"")) | K14: =IF(E14="","",IF(AB14="Siempre","Sí",IF(ISNUMBER(AC14),IF(E14>=AC14,"Sí",IF(AW14>=AC14,"Sí (serie 24 h)","No")),""))) | L14: =IF(E14="","",AA14) | M14: =IF(E14="","",IF(AA14<>"ACUMULA","No aplica",IF(LEFT(K14,2)="Sí","Sí","No"))) | N14: =IF(M14="Sí",AJ14,"") | O14: =IF(M14="Sí",AK14,"") | P14: =IF(AND(LEFT(D14,6)="XIV - ",LEFT(AX14,5)="AVISO"),"Pedimento (R 16): no va al SPPLD",AX14) | Q14: =IF(LEFT(P14,5)="AVISO",IF(ISNUMBER(B14),DATE(YEAR(B14),MONTH(B14)+1,17),"Falta fecha"),"") | R14: =IF(OR(F14="",F14=0),"",IF(ISNUMBER(AG14),IF(F14>=AG14,"PROHIBIDO","Dentro del límite"),"No aplica")) | S14: =IF(E14="","",MID(IF(AQ14=1," · Excede el perfil declarado","")&IF(H14="Sí"," · Paga un tercero","")&IF(J14="Alto"," · Cliente de riesgo alto: DDR (RCG 23 Ter 3 y 4)","")&IF(AND(AS14<>"",AS14<>"No",AS14<>0)," · PEP","")&IF(R14="PROHIBIDO"," · Efectivo prohibido: no lo recibas (Art. 32)","")&IF(AR14=1," · ⚠ Fecha fuera de orden","")&IF(LEFT(I14,1)="⚠"," · ⚠ Cliente no registrado","")&IF(D14=""," · ⚠ Falta la actividad","")&IF(AND(LEFT(P14,5)="AVISO",W14="")," · Captura la cifra total con IVA para el Aviso","")&IF(AND(ISNUMBER(W14),W14<E14)," · ⚠ La cifra con IVA es menor que el monto sin IVA",""),4,400)) | V14: =IF(LEFT(P14,5)<>"AVISO","",IF(T14="Presentado",IF(AND(ISNUMBER(U14),ISNUMBER(Q14),U14>Q14),"Presentado tarde","Presentado"),IF(NOT(ISNUMBER(Q14)),"Falta fecha",IF(Q14<CONFIG!$B$6,"VENCIDO","Vence en "&(Q14-CONFIG!$B$6)&" días")))) | AA14: =IF(AM14="","",INDEX(CATÁLOGO!$D$5:$D$39,AM14)) | AB14: =IF(AM14="","",INDEX(CATÁLOGO!$E$5:$E$39,AM14)) | AC14: =IF(AB14="","",IF(ISNUMBER(AB14),AB14*AV14,AB14)) | AD14: =IF(AM14="","",INDEX(CATÁLOGO!$F$5:$F$39,AM14)) | AE14: =IF(AD14="","",IF(ISNUMBER(AD14),AD14*AV14,AD14)) | AF14: =IF(AM14="","",INDEX(CATÁLOGO!$G$5:$G$39,AM14)) | AG14: =IF(AF14="","",IF(ISNUMBER(AF14),AF14*AV14,AF14)) | AH14: =IF(E14="","",C14&"|"&D14) | AI14: =IF(M14<>"Sí",0,SUMPRODUCT(MAX(($AH$5:AH13=AH14)*($M$5:M13="Sí")*ROW($AH$5:AH13)))) -> 0 | AJ14: =IF(M14<>"Sí","",IF(AL14=1,B14,INDEX($AJ:$AJ,AI14))) | AK14: =IF(M14<>"Sí","",IF(AL14=1,E14,INDEX($AK:$AK,AI14)+E14)) | AL14: =IF(M14<>"Sí","",IF(AI14=0,1,IF(INDEX($AN:$AN,AI14)=0,1,IF(B14>=EDATE(INDEX($AJ:$AJ,AI14),6),1,0)))) | AM14: =IF(D14="","",IFERROR(MATCH(D14,CATÁLOGO!$C$5:$C$39,0),"")) | AN14: =IF(M14<>"Sí","",IF(AND(ISNUMBER(AE14),AK14>=AE14),0,1)) | AO14: =IF(OR(E14="",C14="",NOT(ISNUMBER(B14))),"",SUMIFS($E$6:$E$505,$C$6:$C$505,C14,$B$6:$B$505,">="&DATE(YEAR(B14),MONTH(B14),1),$B$6:$B$505,"<"&DATE(YEAR(B14),MONTH(B14)+1,1))) | AP14: =IF(C14="","",IFERROR(INDEX(CLIENTES!$M$6:$M$305,MATCH(C14,CLIENTES!$A$6:$A$305,0)),"")) | AQ14: =IF(AND(ISNUMBER(AO14),ISNUMBER(AP14)),IF(AND(AP14>0,AO14>AP14),1,0),0) -> 0 | AR14: =IF(NOT(ISNUMBER(B14)),0,IF(B14<MAX($B$5:B13),1,0)) -> 0 | AS14: =IF(C14="","",IFERROR(INDEX(CLIENTES!$H$6:$H$305,MATCH(C14,CLIENTES!$A$6:$A$305,0)),"")) | AT14: =IF(AND(LEFT(P14,5)="AVISO",T14<>"Presentado",ISNUMBER(Q14)),Q14,"") | AU14: =IF(AND(D14="XVI - Activos virtuales (PSAV): operación de intercambio/transferencia",M14="Sí",ISNUMBER(AE14)),IF(AK14>=AE14,1,0),0) -> 0 | AV14: =IF(NOT(ISNUMBER(B14)),CONFIG!$B$4,IFERROR(INDEX(CONFIG!$I$5:$I$14,MATCH(IF(MONTH(B14)=1,YEAR(B14)-1,YEAR(B14)),CONFIG!$H$5:$H$14,0)),CONFIG!$B$4)) -> 117.31 | AW14: =IF(AND(LEFT(D14,4)="I - ",ISNUMBER(B14),C14<>""),SUMIFS($E$6:$E$505,$C$6:$C$505,C14,$D$6:$D$505,D14,$B$6:$B$505,">"&(B14-1),$B$6:$B$505,"<="&B14),0) -> 0 | AX14: =IF(E14="","",IF(AD14="Siempre","AVISO (siempre)",IF(AD14="No aplica","Sin Aviso (sólo preparas: Ley 17 XI)",IF(NOT(ISNUMBER(AE14)),"",IF(AA14<>"ACUMULA",IF(E14>=AE14,IF(AND(D14="XVI - Activos virtuales (PSAV): cobro de contraprestación (comisión) por el servicio",COUNTIFS($C$6:$C$505,C14,$B$6:$B$505,">="&INT(B14),$B$6:$B$505,"<"&(INT(B14)+1),$AU$6:$AU$505,1)>0),"En el Aviso del inciso a) (R 31 Bis)","AVISO"),"—"),IF(M14<>"Sí","—",IF(AK14>=AE14,IF(AK14=E14,"AVISO","AVISO (acumulado)"),"Acumulando")))))))
A15: =IF(E15="","",ROW()-5) | I15: =IF(C15="","",IFERROR(INDEX(CLIENTES!$B$6:$B$305,MATCH(C15,CLIENTES!$A$6:$A$305,0)),"⚠ ID no registrado")) | J15: =IF(C15="","",IFERROR(INDEX(CLIENTES!$Z$6:$Z$305,MATCH(C15,CLIENTES!$A$6:$A$305,0)),"")) | K15: =IF(E15="","",IF(AB15="Siempre","Sí",IF(ISNUMBER(AC15),IF(E15>=AC15,"Sí",IF(AW15>=AC15,"Sí (serie 24 h)","No")),""))) | L15: =IF(E15="","",AA15) | M15: =IF(E15="","",IF(AA15<>"ACUMULA","No aplica",IF(LEFT(K15,2)="Sí","Sí","No"))) | N15: =IF(M15="Sí",AJ15,"") | O15: =IF(M15="Sí",AK15,"") | P15: =IF(AND(LEFT(D15,6)="XIV - ",LEFT(AX15,5)="AVISO"),"Pedimento (R 16): no va al SPPLD",AX15) | Q15: =IF(LEFT(P15,5)="AVISO",IF(ISNUMBER(B15),DATE(YEAR(B15),MONTH(B15)+1,17),"Falta fecha"),"") | R15: =IF(OR(F15="",F15=0),"",IF(ISNUMBER(AG15),IF(F15>=AG15,"PROHIBIDO","Dentro del límite"),"No aplica")) | S15: =IF(E15="","",MID(IF(AQ15=1," · Excede el perfil declarado","")&IF(H15="Sí"," · Paga un tercero","")&IF(J15="Alto"," · Cliente de riesgo alto: DDR (RCG 23 Ter 3 y 4)","")&IF(AND(AS15<>"",AS15<>"No",AS15<>0)," · PEP","")&IF(R15="PROHIBIDO"," · Efectivo prohibido: no lo recibas (Art. 32)","")&IF(AR15=1," · ⚠ Fecha fuera de orden","")&IF(LEFT(I15,1)="⚠"," · ⚠ Cliente no registrado","")&IF(D15=""," · ⚠ Falta la actividad","")&IF(AND(LEFT(P15,5)="AVISO",W15="")," · Captura la cifra total con IVA para el Aviso","")&IF(AND(ISNUMBER(W15),W15<E15)," · ⚠ La cifra con IVA es menor que el monto sin IVA",""),4,400)) | V15: =IF(LEFT(P15,5)<>"AVISO","",IF(T15="Presentado",IF(AND(ISNUMBER(U15),ISNUMBER(Q15),U15>Q15),"Presentado tarde","Presentado"),IF(NOT(ISNUMBER(Q15)),"Falta fecha",IF(Q15<CONFIG!$B$6,"VENCIDO","Vence en "&(Q15-CONFIG!$B$6)&" días")))) | AA15: =IF(AM15="","",INDEX(CATÁLOGO!$D$5:$D$39,AM15)) | AB15: =IF(AM15="","",INDEX(CATÁLOGO!$E$5:$E$39,AM15)) | AC15: =IF(AB15="","",IF(ISNUMBER(AB15),AB15*AV15,AB15)) | AD15: =IF(AM15="","",INDEX(CATÁLOGO!$F$5:$F$39,AM15)) | AE15: =IF(AD15="","",IF(ISNUMBER(AD15),AD15*AV15,AD15)) | AF15: =IF(AM15="","",INDEX(CATÁLOGO!$G$5:$G$39,AM15)) | AG15: =IF(AF15="","",IF(ISNUMBER(AF15),AF15*AV15,AF15)) | AH15: =IF(E15="","",C15&"|"&D15) | AI15: =IF(M15<>"Sí",0,SUMPRODUCT(MAX(($AH$5:AH14=AH15)*($M$5:M14="Sí")*ROW($AH$5:AH14)))) -> 0 | AJ15: =IF(M15<>"Sí","",IF(AL15=1,B15,INDEX($AJ:$AJ,AI15))) | AK15: =IF(M15<>"Sí","",IF(AL15=1,E15,INDEX($AK:$AK,AI15)+E15)) | AL15: =IF(M15<>"Sí","",IF(AI15=0,1,IF(INDEX($AN:$AN,AI15)=0,1,IF(B15>=EDATE(INDEX($AJ:$AJ,AI15),6),1,0)))) | AM15: =IF(D15="","",IFERROR(MATCH(D15,CATÁLOGO!$C$5:$C$39,0),"")) | AN15: =IF(M15<>"Sí","",IF(AND(ISNUMBER(AE15),AK15>=AE15),0,1)) | AO15: =IF(OR(E15="",C15="",NOT(ISNUMBER(B15))),"",SUMIFS($E$6:$E$505,$C$6:$C$505,C15,$B$6:$B$505,">="&DATE(YEAR(B15),MONTH(B15),1),$B$6:$B$505,"<"&DATE(YEAR(B15),MONTH(B15)+1,1))) | AP15: =IF(C15="","",IFERROR(INDEX(CLIENTES!$M$6:$M$305,MATCH(C15,CLIENTES!$A$6:$A$305,0)),"")) | AQ15: =IF(AND(ISNUMBER(AO15),ISNUMBER(AP15)),IF(AND(AP15>0,AO15>AP15),1,0),0) -> 0 | AR15: =IF(NOT(ISNUMBER(B15)),0,IF(B15<MAX($B$5:B14),1,0)) -> 0 | AS15: =IF(C15="","",IFERROR(INDEX(CLIENTES!$H$6:$H$305,MATCH(C15,CLIENTES!$A$6:$A$305,0)),"")) | AT15: =IF(AND(LEFT(P15,5)="AVISO",T15<>"Presentado",ISNUMBER(Q15)),Q15,"") | AU15: =IF(AND(D15="XVI - Activos virtuales (PSAV): operación de intercambio/transferencia",M15="Sí",ISNUMBER(AE15)),IF(AK15>=AE15,1,0),0) -> 0 | AV15: =IF(NOT(ISNUMBER(B15)),CONFIG!$B$4,IFERROR(INDEX(CONFIG!$I$5:$I$14,MATCH(IF(MONTH(B15)=1,YEAR(B15)-1,YEAR(B15)),CONFIG!$H$5:$H$14,0)),CONFIG!$B$4)) -> 117.31 | AW15: =IF(AND(LEFT(D15,4)="I - ",ISNUMBER(B15),C15<>""),SUMIFS($E$6:$E$505,$C$6:$C$505,C15,$D$6:$D$505,D15,$B$6:$B$505,">"&(B15-1),$B$6:$B$505,"<="&B15),0) -> 0 | AX15: =IF(E15="","",IF(AD15="Siempre","AVISO (siempre)",IF(AD15="No aplica","Sin Aviso (sólo preparas: Ley 17 XI)",IF(NOT(ISNUMBER(AE15)),"",IF(AA15<>"ACUMULA",IF(E15>=AE15,IF(AND(D15="XVI - Activos virtuales (PSAV): cobro de contraprestación (comisión) por el servicio",COUNTIFS($C$6:$C$505,C15,$B$6:$B$505,">="&INT(B15),$B$6:$B$505,"<"&(INT(B15)+1),$AU$6:$AU$505,1)>0),"En el Aviso del inciso a) (R 31 Bis)","AVISO"),"—"),IF(M15<>"Sí","—",IF(AK15>=AE15,IF(AK15=E15,"AVISO","AVISO (acumulado)"),"Acumulando")))))))
A16: =IF(E16="","",ROW()-5) | I16: =IF(C16="","",IFERROR(INDEX(CLIENTES!$B$6:$B$305,MATCH(C16,CLIENTES!$A$6:$A$305,0)),"⚠ ID no registrado")) | J16: =IF(C16="","",IFERROR(INDEX(CLIENTES!$Z$6:$Z$305,MATCH(C16,CLIENTES!$A$6:$A$305,0)),"")) | K16: =IF(E16="","",IF(AB16="Siempre","Sí",IF(ISNUMBER(AC16),IF(E16>=AC16,"Sí",IF(AW16>=AC16,"Sí (serie 24 h)","No")),""))) | L16: =IF(E16="","",AA16) | M16: =IF(E16="","",IF(AA16<>"ACUMULA","No aplica",IF(LEFT(K16,2)="Sí","Sí","No"))) | N16: =IF(M16="Sí",AJ16,"") | O16: =IF(M16="Sí",AK16,"") | P16: =IF(AND(LEFT(D16,6)="XIV - ",LEFT(AX16,5)="AVISO"),"Pedimento (R 16): no va al SPPLD",AX16) | Q16: =IF(LEFT(P16,5)="AVISO",IF(ISNUMBER(B16),DATE(YEAR(B16),MONTH(B16)+1,17),"Falta fecha"),"") | R16: =IF(OR(F16="",F16=0),"",IF(ISNUMBER(AG16),IF(F16>=AG16,"PROHIBIDO","Dentro del límite"),"No aplica")) | S16: =IF(E16="","",MID(IF(AQ16=1," · Excede el perfil declarado","")&IF(H16="Sí"," · Paga un tercero","")&IF(J16="Alto"," · Cliente de riesgo alto: DDR (RCG 23 Ter 3 y 4)","")&IF(AND(AS16<>"",AS16<>"No",AS16<>0)," · PEP","")&IF(R16="PROHIBIDO"," · Efectivo prohibido: no lo recibas (Art. 32)","")&IF(AR16=1," · ⚠ Fecha fuera de orden","")&IF(LEFT(I16,1)="⚠"," · ⚠ Cliente no registrado","")&IF(D16=""," · ⚠ Falta la actividad","")&IF(AND(LEFT(P16,5)="AVISO",W16="")," · Captura la cifra total con IVA para el Aviso","")&IF(AND(ISNUMBER(W16),W16<E16)," · ⚠ La cifra con IVA es menor que el monto sin IVA",""),4,400)) | V16: =IF(LEFT(P16,5)<>"AVISO","",IF(T16="Presentado",IF(AND(ISNUMBER(U16),ISNUMBER(Q16),U16>Q16),"Presentado tarde","Presentado"),IF(NOT(ISNUMBER(Q16)),"Falta fecha",IF(Q16<CONFIG!$B$6,"VENCIDO","Vence en "&(Q16-CONFIG!$B$6)&" días")))) | AA16: =IF(AM16="","",INDEX(CATÁLOGO!$D$5:$D$39,AM16)) | AB16: =IF(AM16="","",INDEX(CATÁLOGO!$E$5:$E$39,AM16)) | AC16: =IF(AB16="","",IF(ISNUMBER(AB16),AB16*AV16,AB16)) | AD16: =IF(AM16="","",INDEX(CATÁLOGO!$F$5:$F$39,AM16)) | AE16: =IF(AD16="","",IF(ISNUMBER(AD16),AD16*AV16,AD16)) | AF16: =IF(AM16="","",INDEX(CATÁLOGO!$G$5:$G$39,AM16)) | AG16: =IF(AF16="","",IF(ISNUMBER(AF16),AF16*AV16,AF16)) | AH16: =IF(E16="","",C16&"|"&D16) | AI16: =IF(M16<>"Sí",0,SUMPRODUCT(MAX(($AH$5:AH15=AH16)*($M$5:M15="Sí")*ROW($AH$5:AH15)))) -> 0 | AJ16: =IF(M16<>"Sí","",IF(AL16=1,B16,INDEX($AJ:$AJ,AI16))) | AK16: =IF(M16<>"Sí","",IF(AL16=1,E16,INDEX($AK:$AK,AI16)+E16)) | AL16: =IF(M16<>"Sí","",IF(AI16=0,1,IF(INDEX($AN:$AN,AI16)=0,1,IF(B16>=EDATE(INDEX($AJ:$AJ,AI16),6),1,0)))) | AM16: =IF(D16="","",IFERROR(MATCH(D16,CATÁLOGO!$C$5:$C$39,0),"")) | AN16: =IF(M16<>"Sí","",IF(AND(ISNUMBER(AE16),AK16>=AE16),0,1)) | AO16: =IF(OR(E16="",C16="",NOT(ISNUMBER(B16))),"",SUMIFS($E$6:$E$505,$C$6:$C$505,C16,$B$6:$B$505,">="&DATE(YEAR(B16),MONTH(B16),1),$B$6:$B$505,"<"&DATE(YEAR(B16),MONTH(B16)+1,1))) | AP16: =IF(C16="","",IFERROR(INDEX(CLIENTES!$M$6:$M$305,MATCH(C16,CLIENTES!$A$6:$A$305,0)),"")) | AQ16: =IF(AND(ISNUMBER(AO16),ISNUMBER(AP16)),IF(AND(AP16>0,AO16>AP16),1,0),0) -> 0 | AR16: =IF(NOT(ISNUMBER(B16)),0,IF(B16<MAX($B$5:B15),1,0)) -> 0 | AS16: =IF(C16="","",IFERROR(INDEX(CLIENTES!$H$6:$H$305,MATCH(C16,CLIENTES!$A$6:$A$305,0)),"")) | AT16: =IF(AND(LEFT(P16,5)="AVISO",T16<>"Presentado",ISNUMBER(Q16)),Q16,"") | AU16: =IF(AND(D16="XVI - Activos virtuales (PSAV): operación de intercambio/transferencia",M16="Sí",ISNUMBER(AE16)),IF(AK16>=AE16,1,0),0) -> 0 | AV16: =IF(NOT(ISNUMBER(B16)),CONFIG!$B$4,IFERROR(INDEX(CONFIG!$I$5:$I$14,MATCH(IF(MONTH(B16)=1,YEAR(B16)-1,YEAR(B16)),CONFIG!$H$5:$H$14,0)),CONFIG!$B$4)) -> 117.31 | AW16: =IF(AND(LEFT(D16,4)="I - ",ISNUMBER(B16),C16<>""),SUMIFS($E$6:$E$505,$C$6:$C$505,C16,$D$6:$D$505,D16,$B$6:$B$505,">"&(B16-1),$B$6:$B$505,"<="&B16),0) -> 0 | AX16: =IF(E16="","",IF(AD16="Siempre","AVISO (siempre)",IF(AD16="No aplica","Sin Aviso (sólo preparas: Ley 17 XI)",IF(NOT(ISNUMBER(AE16)),"",IF(AA16<>"ACUMULA",IF(E16>=AE16,IF(AND(D16="XVI - Activos virtuales (PSAV): cobro de contraprestación (comisión) por el servicio",COUNTIFS($C$6:$C$505,C16,$B$6:$B$505,">="&INT(B16),$B$6:$B$505,"<"&(INT(B16)+1),$AU$6:$AU$505,1)>0),"En el Aviso del inciso a) (R 31 Bis)","AVISO"),"—"),IF(M16<>"Sí","—",IF(AK16>=AE16,IF(AK16=E16,"AVISO","AVISO (acumulado)"),"Acumulando")))))))
A17: =IF(E17="","",ROW()-5) | I17: =IF(C17="","",IFERROR(INDEX(CLIENTES!$B$6:$B$305,MATCH(C17,CLIENTES!$A$6:$A$305,0)),"⚠ ID no registrado")) | J17: =IF(C17="","",IFERROR(INDEX(CLIENTES!$Z$6:$Z$305,MATCH(C17,CLIENTES!$A$6:$A$305,0)),"")) | K17: =IF(E17="","",IF(AB17="Siempre","Sí",IF(ISNUMBER(AC17),IF(E17>=AC17,"Sí",IF(AW17>=AC17,"Sí (serie 24 h)","No")),""))) | L17: =IF(E17="","",AA17) | M17: =IF(E17="","",IF(AA17<>"ACUMULA","No aplica",IF(LEFT(K17,2)="Sí","Sí","No"))) | N17: =IF(M17="Sí",AJ17,"") | O17: =IF(M17="Sí",AK17,"") | P17: =IF(AND(LEFT(D17,6)="XIV - ",LEFT(AX17,5)="AVISO"),"Pedimento (R 16): no va al SPPLD",AX17) | Q17: =IF(LEFT(P17,5)="AVISO",IF(ISNUMBER(B17),DATE(YEAR(B17),MONTH(B17)+1,17),"Falta fecha"),"") | R17: =IF(OR(F17="",F17=0),"",IF(ISNUMBER(AG17),IF(F17>=AG17,"PROHIBIDO","Dentro del límite"),"No aplica")) | S17: =IF(E17="","",MID(IF(AQ17=1," · Excede el perfil declarado","")&IF(H17="Sí"," · Paga un tercero","")&IF(J17="Alto"," · Cliente de riesgo alto: DDR (RCG 23 Ter 3 y 4)","")&IF(AND(AS17<>"",AS17<>"No",AS17<>0)," · PEP","")&IF(R17="PROHIBIDO"," · Efectivo prohibido: no lo recibas (Art. 32)","")&IF(AR17=1," · ⚠ Fecha fuera de orden","")&IF(LEFT(I17,1)="⚠"," · ⚠ Cliente no registrado","")&IF(D17=""," · ⚠ Falta la actividad","")&IF(AND(LEFT(P17,5)="AVISO",W17="")," · Captura la cifra total con IVA para el Aviso","")&IF(AND(ISNUMBER(W17),W17<E17)," · ⚠ La cifra con IVA es menor que el monto sin IVA",""),4,400)) | V17: =IF(LEFT(P17,5)<>"AVISO","",IF(T17="Presentado",IF(AND(ISNUMBER(U17),ISNUMBER(Q17),U17>Q17),"Presentado tarde","Presentado"),IF(NOT(ISNUMBER(Q17)),"Falta fecha",IF(Q17<CONFIG!$B$6,"VENCIDO","Vence en "&(Q17-CONFIG!$B$6)&" días")))) | AA17: =IF(AM17="","",INDEX(CATÁLOGO!$D$5:$D$39,AM17)) | AB17: =IF(AM17="","",INDEX(CATÁLOGO!$E$5:$E$39,AM17)) | AC17: =IF(AB17="","",IF(ISNUMBER(AB17),AB17*AV17,AB17)) | AD17: =IF(AM17="","",INDEX(CATÁLOGO!$F$5:$F$39,AM17)) | AE17: =IF(AD17="","",IF(ISNUMBER(AD17),AD17*AV17,AD17)) | AF17: =IF(AM17="","",INDEX(CATÁLOGO!$G$5:$G$39,AM17)) | AG17: =IF(AF17="","",IF(ISNUMBER(AF17),AF17*AV17,AF17)) | AH17: =IF(E17="","",C17&"|"&D17) | AI17: =IF(M17<>"Sí",0,SUMPRODUCT(MAX(($AH$5:AH16=AH17)*($M$5:M16="Sí")*ROW($AH$5:AH16)))) -> 0 | AJ17: =IF(M17<>"Sí","",IF(AL17=1,B17,INDEX($AJ:$AJ,AI17))) | AK17: =IF(M17<>"Sí","",IF(AL17=1,E17,INDEX($AK:$AK,AI17)+E17)) | AL17: =IF(M17<>"Sí","",IF(AI17=0,1,IF(INDEX($AN:$AN,AI17)=0,1,IF(B17>=EDATE(INDEX($AJ:$AJ,AI17),6),1,0)))) | AM17: =IF(D17="","",IFERROR(MATCH(D17,CATÁLOGO!$C$5:$C$39,0),"")) | AN17: =IF(M17<>"Sí","",IF(AND(ISNUMBER(AE17),AK17>=AE17),0,1)) | AO17: =IF(OR(E17="",C17="",NOT(ISNUMBER(B17))),"",SUMIFS($E$6:$E$505,$C$6:$C$505,C17,$B$6:$B$505,">="&DATE(YEAR(B17),MONTH(B17),1),$B$6:$B$505,"<"&DATE(YEAR(B17),MONTH(B17)+1,1))) | AP17: =IF(C17="","",IFERROR(INDEX(CLIENTES!$M$6:$M$305,MATCH(C17,CLIENTES!$A$6:$A$305,0)),"")) | AQ17: =IF(AND(ISNUMBER(AO17),ISNUMBER(AP17)),IF(AND(AP17>0,AO17>AP17),1,0),0) -> 0 | AR17: =IF(NOT(ISNUMBER(B17)),0,IF(B17<MAX($B$5:B16),1,0)) -> 0 | AS17: =IF(C17="","",IFERROR(INDEX(CLIENTES!$H$6:$H$305,MATCH(C17,CLIENTES!$A$6:$A$305,0)),"")) | AT17: =IF(AND(LEFT(P17,5)="AVISO",T17<>"Presentado",ISNUMBER(Q17)),Q17,"") | AU17: =IF(AND(D17="XVI - Activos virtuales (PSAV): operación de intercambio/transferencia",M17="Sí",ISNUMBER(AE17)),IF(AK17>=AE17,1,0),0) -> 0 | AV17: =IF(NOT(ISNUMBER(B17)),CONFIG!$B$4,IFERROR(INDEX(CONFIG!$I$5:$I$14,MATCH(IF(MONTH(B17)=1,YEAR(B17)-1,YEAR(B17)),CONFIG!$H$5:$H$14,0)),CONFIG!$B$4)) -> 117.31 | AW17: =IF(AND(LEFT(D17,4)="I - ",ISNUMBER(B17),C17<>""),SUMIFS($E$6:$E$505,$C$6:$C$505,C17,$D$6:$D$505,D17,$B$6:$B$505,">"&(B17-1),$B$6:$B$505,"<="&B17),0) -> 0 | AX17: =IF(E17="","",IF(AD17="Siempre","AVISO (siempre)",IF(AD17="No aplica","Sin Aviso (sólo preparas: Ley 17 XI)",IF(NOT(ISNUMBER(AE17)),"",IF(AA17<>"ACUMULA",IF(E17>=AE17,IF(AND(D17="XVI - Activos virtuales (PSAV): cobro de contraprestación (comisión) por el servicio",COUNTIFS($C$6:$C$505,C17,$B$6:$B$505,">="&INT(B17),$B$6:$B$505,"<"&(INT(B17)+1),$AU$6:$AU$505,1)>0),"En el Aviso del inciso a) (R 31 Bis)","AVISO"),"—"),IF(M17<>"Sí","—",IF(AK17>=AE17,IF(AK17=E17,"AVISO","AVISO (acumulado)"),"Acumulando")))))))
